2022-11-20 01:08:07,802 INFO    StreamThr :24164 [internal.py:wandb_internal():88] W&B internal server running at pid: 24164, started at: 2022-11-20 01:08:07.802592
2022-11-20 01:08:07,803 DEBUG   HandlerThread:24164 [handler.py:handle_request():139] handle_request: status
2022-11-20 01:08:07,805 DEBUG   SenderThread:24164 [sender.py:send_request():317] send_request: status
2022-11-20 01:08:07,807 DEBUG   SenderThread:24164 [sender.py:send():303] send: header
2022-11-20 01:08:07,807 INFO    WriterThread:24164 [datastore.py:open_for_write():75] open: c:\Users\Sebastian Cavada\Documents\SCSV\Projects\HackaTUM\machine-learning\pytorch\train\wandb\run-20221120_010807-1dw0kfti\run-1dw0kfti.wandb
2022-11-20 01:08:07,852 DEBUG   SenderThread:24164 [sender.py:send():303] send: run
2022-11-20 01:08:08,212 ERROR   SenderThread:24164 [internal_api.py:execute():213] 403 response executing GraphQL.
2022-11-20 01:08:08,212 ERROR   SenderThread:24164 [internal_api.py:execute():214] {"errors":[{"message":"permission denied","path":["upsertBucket"],"extensions":{"code":"PERMISSION_ERROR"}}],"data":{"upsertBucket":null}}
2022-11-20 01:08:08,856 INFO    HandlerThread:24164 [handler.py:finish():814] shutting down handler
2022-11-20 01:08:08,856 INFO    WriterThread:24164 [datastore.py:close():279] close: c:\Users\Sebastian Cavada\Documents\SCSV\Projects\HackaTUM\machine-learning\pytorch\train\wandb\run-20221120_010807-1dw0kfti\run-1dw0kfti.wandb
2022-11-20 01:08:08,857 ERROR   StreamThr :24164 [internal.py:wandb_internal():163] Thread SenderThread:
Traceback (most recent call last):
  File "c:\Users\Sebastian Cavada\anaconda3\envs\cv\lib\site-packages\wandb\sdk\lib\retry.py", line 113, in __call__
    result = self._call_fn(*args, **kwargs)
  File "c:\Users\Sebastian Cavada\anaconda3\envs\cv\lib\site-packages\wandb\sdk\internal\internal_api.py", line 210, in execute
    return self.client.execute(*args, **kwargs)  # type: ignore
  File "c:\Users\Sebastian Cavada\anaconda3\envs\cv\lib\site-packages\wandb\vendor\gql-0.2.0\wandb_gql\client.py", line 52, in execute
    result = self._get_result(document, *args, **kwargs)
  File "c:\Users\Sebastian Cavada\anaconda3\envs\cv\lib\site-packages\wandb\vendor\gql-0.2.0\wandb_gql\client.py", line 60, in _get_result
    return self.transport.execute(document, *args, **kwargs)
  File "c:\Users\Sebastian Cavada\anaconda3\envs\cv\lib\site-packages\wandb\vendor\gql-0.2.0\wandb_gql\transport\requests.py", line 39, in execute
    request.raise_for_status()
  File "c:\Users\Sebastian Cavada\anaconda3\envs\cv\lib\site-packages\requests\models.py", line 1021, in raise_for_status
    raise HTTPError(http_error_msg, response=self)
requests.exceptions.HTTPError: 403 Client Error: Forbidden for url: https://api.wandb.ai/graphql

During handling of the above exception, another exception occurred:

Traceback (most recent call last):
  File "c:\Users\Sebastian Cavada\anaconda3\envs\cv\lib\site-packages\wandb\apis\normalize.py", line 26, in wrapper
    return func(*args, **kwargs)
  File "c:\Users\Sebastian Cavada\anaconda3\envs\cv\lib\site-packages\wandb\sdk\internal\internal_api.py", line 1516, in upsert_run
    response = self.gql(
  File "c:\Users\Sebastian Cavada\anaconda3\envs\cv\lib\site-packages\wandb\sdk\lib\retry.py", line 129, in __call__
    retry_timedelta_triggered = check_retry_fn(e)
  File "c:\Users\Sebastian Cavada\anaconda3\envs\cv\lib\site-packages\wandb\util.py", line 1049, in check_retry_fn
    return fallback_retry_fn(e)
  File "c:\Users\Sebastian Cavada\anaconda3\envs\cv\lib\site-packages\wandb\util.py", line 996, in no_retry_auth
    raise CommError("Permission denied, ask the project owner to grant you access")
wandb.errors.CommError: Permission denied, ask the project owner to grant you access

During handling of the above exception, another exception occurred:

Traceback (most recent call last):
  File "c:\Users\Sebastian Cavada\anaconda3\envs\cv\lib\site-packages\wandb\sdk\internal\internal_util.py", line 50, in run
    self._run()
  File "c:\Users\Sebastian Cavada\anaconda3\envs\cv\lib\site-packages\wandb\sdk\internal\internal_util.py", line 101, in _run
    self._process(record)
  File "c:\Users\Sebastian Cavada\anaconda3\envs\cv\lib\site-packages\wandb\sdk\internal\internal.py", line 308, in _process
    self._sm.send(record)
  File "c:\Users\Sebastian Cavada\anaconda3\envs\cv\lib\site-packages\wandb\sdk\internal\sender.py", line 305, in send
    send_handler(record)
  File "c:\Users\Sebastian Cavada\anaconda3\envs\cv\lib\site-packages\wandb\sdk\internal\sender.py", line 797, in send_run
    self._init_run(run, config_value_dict)
  File "c:\Users\Sebastian Cavada\anaconda3\envs\cv\lib\site-packages\wandb\sdk\internal\sender.py", line 823, in _init_run
    server_run, inserted, server_messages = self._api.upsert_run(
  File "c:\Users\Sebastian Cavada\anaconda3\envs\cv\lib\site-packages\wandb\apis\normalize.py", line 62, in wrapper
    raise CommError(message, err).with_traceback(sys.exc_info()[2])
  File "c:\Users\Sebastian Cavada\anaconda3\envs\cv\lib\site-packages\wandb\apis\normalize.py", line 26, in wrapper
    return func(*args, **kwargs)
  File "c:\Users\Sebastian Cavada\anaconda3\envs\cv\lib\site-packages\wandb\sdk\internal\internal_api.py", line 1516, in upsert_run
    response = self.gql(
  File "c:\Users\Sebastian Cavada\anaconda3\envs\cv\lib\site-packages\wandb\sdk\lib\retry.py", line 129, in __call__
    retry_timedelta_triggered = check_retry_fn(e)
  File "c:\Users\Sebastian Cavada\anaconda3\envs\cv\lib\site-packages\wandb\util.py", line 1049, in check_retry_fn
    return fallback_retry_fn(e)
  File "c:\Users\Sebastian Cavada\anaconda3\envs\cv\lib\site-packages\wandb\util.py", line 996, in no_retry_auth
    raise CommError("Permission denied, ask the project owner to grant you access")
wandb.errors.CommError: Permission denied, ask the project owner to grant you access
